Workbook

Sheet Leggimi
A1: Impianto birrificio: elenco completo, costi e business plan
A2: ="Vendite a regime: "&Parametri!C19&" fusti e "&Parametri!C20&" bottiglie all'anno ("&ROUND(Parametri!C26*100,0)&"% del volume in fusti). Preparato il 06/10/2026, aggiornato il 07/10/2026 (mutuo, 15 anni, clienti, vendite in n. di fusti e bottiglie)." -> Vendite a regime: 144 fusti e 3300 bottiglie all'anno (80% del volume in fusti). Preparato il 06/10/2026, aggiornato il 07/10/2026 (mutuo, 15 anni, clienti, vendite in n. di fusti e bottiglie).
A4: Cosa contiene
A5: Riepilogo | B5: Impianto scelto: investimento, capacità, ricavi, utile, payback, punto di pareggio.
A6: Mercato | B6: Dati Assobirra 2025, prezzi di riferimento, SWOT.
A7: Normativa e fisco | B7: Autorizzazioni (SUAP, ASL, ADM), accise, regime fiscale.
A8: Parametri | B8: Tutte le ipotesi (modificabili, celle blu), compresi i dati del mutuo (sezione 8).
A9: Impianto e costi | B9: Elenco completo di macchinari, locale e avvio, con costo di ogni voce (impianto scelto).
A10: Materie prime | B10: Ricette tipo, consumi e costo per ettolitro e per cotta.
A11: Business plan | B11: Business plan a 15 anni dell'impianto scelto, senza mutuo (righe 4–58) e con mutuo (righe 60–79).
A12: Cadenza produzione | B12: Rotazione dei 3 fermentatori con una cotta a settimana e carico di lavoro.
A13: Break-even | B13: Litri da vendere per il pareggio e per rientrare in 5 anni.
A14: Cronoprogramma | B14: Tempi indicativi di avvio.
A15: Checklist locale | B15: Punti da verificare nel sopralluogo e voci di costo collegate.
A16: Fonti | B16: Link alle fonti usate.
A17: Clienti potenziali | B17: Pub, bar, ristoranti, agriturismi e altri locali nel raggio di 30 km, con priorità, stima di fusti e stato dei contatti; elenco dei birrifici concorrenti.
A19: Convenzioni
A20: Blu | B20: Ipotesi o dati inseriti da modificare.
A21: Nero | B21: Formule.
A22: Verde | B22: Collegamenti ad altri fogli.
A24: Situazione dichiarata (06/10/2026)
A25: Locale | B25: Di proprietà (affitto 0), 40–80 m², stato da verificare; il socio è architetto.
A26: Soci e fisco | B26: Due soci non familiari, SRL (forfettario escluso), entrambi con un altro lavoro.
A27: Compensi | B27: Nessun compenso ai soci: gli utili restano nella società e il tempo di lavoro non viene valorizzato.
A28: Obiettivo | B28: Secondo lavoro che si autofinanzia; 20–30 ore a settimana in due. Il budget iniziale era 30.000 €, ma l'impianto scelto lo supera (vedi Riepilogo, investimento totale): per questo è previsto un mutuo.
A29: Vendite | B29: Fusti per eventi e feste (oggi da 2–5 al mese, obiettivo dichiarato 8–10). Il modello a regime assume i fusti e le bottiglie all'anno indicati in Parametri (oggi ≈ 17 fusti da 30 L al mese): è molto di più, da verificare con preordini ed eventi. Bottiglie a pub e bar; attrezzatura usata valutata caso per caso.
A31: Avvertenze
A32: 1 | B32: Molti costi sono stime mie (colonna Tipo = S): vanno sostituiti con preventivi reali.
A33: 2 | B33: I fermentatori UT-200 PRO sono su ordinazione: chiedere a BrewTaurus conferma di prezzo, tempi e documenti PED. Mulino, trasporto e molte voci di contorno non sono verificati.
A34: 3 | B34: Le informazioni su normativa e fisco sono sintesi di fonti pubbliche: verificare con commercialista, SUAP, ASL e ADM.
A35: 4 | B35: I risultati dipendono molto dai volumi di vendita: il modello non garantisce che i clienti ci siano.
A36: 5 | B36: Il tasso del mutuo (Parametri riga 102) è un'ipotesi mia: per piccoli importi i dati 2026 indicano tassi più alti. Sostituirlo con preventivi di banca o Confidi. Istruttoria, imposta sostitutiva e spese di gestione del mutuo non sono incluse.

Sheet Riepilogo
A1: Riepilogo: impianto completo e business plan
A2: Impianto scelto: K220 2V + 3 UT-200 con i fusti e le bottiglie all'anno dei Parametri. Tutto collegato ai fogli di dettaglio.
A4: Indicatore | B4: K220 2V + 3×UT-200 | C4: Commento
A5: Investimento totale (con imprevisti e circolante) | B5: ='Impianto e costi'!G73 -> 60311.691 | C5: Comprende macchinari, locale, avvio e capitale circolante
A6: di cui macchinari e impianti (A–E) | B6: ='Impianto e costi'!G17+'Impianto e costi'!G26+'Impianto e costi'!G34+'Impianto e costi'!G41+'Impianto e costi'!G54 -> 53123
A7: di cui avvio e autorizzazioni (F) | B7: ='Impianto e costi'!G66 -> 4300
A8: Capacità produttiva (hl/anno) | B8: =Parametri!C17 -> 82.8 | C8: Limitata dai fermentatori, non dalla sala cottura
A9: Ricavi anno 3 | B9: ='Business plan'!E17 -> 20298
A10: Ricavi a regime (anno 5) | B10: ='Business plan'!G17 -> 23880
A11: EBITDA a regime (margine operativo) | B11: ='Business plan'!G43 -> 11126.763 | C11: Ricavi − costi variabili − costi fissi. Se negativo, i costi fissi superano il margine delle vendite
A12: Utile netto a regime | B12: ='Business plan'!G47 -> 4051.4601
A13: Ore di lavoro a settimana in due (stima, non valorizzate) | B13: ='Business plan'!G49/Parametri!$C$12 -> 9.7444746 | C13: Voi avete 20–30 ore a settimana disponibili
A14: Payback senza mutuo (anni) | B14: ='Business plan'!B56 -> 7.8678594 | C14: 'oltre 15 anni' = l'investimento non rientra nel periodo
A15: EBITDA a regime senza affitto | B15: ='Business plan'!G43+Parametri!$C$73*12 -> 11126.763 | C15: Come la riga 11 se l'affitto è 0 (locale di proprietà)
A16: Payback semplice (anni) – approssimato, senza affitto | B16: =IF(B15>0,B5/B15,"non rientra") -> 5.4204164 | C16: Investimento ÷ EBITDA; ignora imposte e ramp-up
A17: Litri da vendere per il pareggio operativo | B17: ='Break-even'!C12 -> 1837.6587
A18: …in percentuale della capacità vendibile | B18: ='Break-even'!C14 -> 0.23118693 | C18: Oltre 100% = pareggio oltre la capacità
A19: Litri da vendere per rientrare in 5 anni | B19: ='Break-even'!C16 -> 5709.2901
A20: …in percentuale della capacità vendibile | B20: ='Break-even'!C17 -> 0.71825812
A21: Volume venduto a regime (hl/anno) | B21: ='Business plan'!G8/100 -> 54.09 | C21: ="Fusti + bottiglie dei Parametri. Utilizzo della capacità: "&ROUND(Parametri!C32*100,0)&"% (controllo: "&Parametri!C33&")" -> Fusti + bottiglie dei Parametri. Utilizzo della capacità: 68% (controllo: OK)
A22: EBITDA a regime se l'INPS fosse dovuta (2 persone, contributo minimo) | B22: ='Business plan'!G43+'Business plan'!G35-2*(Parametri!$C$79*Parametri!$C$78+Parametri!$C$81) -> 2084.0434 | C22: Da verificare con il commercialista: con un altro lavoro l'obbligo può non scattare
A23: ="Fusti da "&Parametri!C21&" L al mese necessari per il pareggio (stesso mix fusti/bottiglie)" -> Fusti da 30 L al mese necessari per il pareggio (stesso mix fusti/bottiglie) | B23: =IF(ISNUMBER('Break-even'!C12),'Break-even'!C12*Parametri!$C$26/Parametri!$C$21/12,"n/d") -> 4.0768911 | C23: Da confrontare con i fusti/mese previsti nei Parametri
A24: Come leggere i risultati
A25: ="• Un solo impianto: K220 2V (brewhouse da 220 L, batch "&Parametri!C7&" L) con "&Parametri!C8&" UT-200 PRO a rotazione, acqua calda separata per lo sparge e CIP kit manuale. Una cotta a settimana a regime: ≈ "&ROUND(Parametri!C15,0)&" cotte e ≈ "&ROUND(Parametri!C17,0)&" hl di produzione all'anno (vedi foglio Cadenza produzione)." -> • Un solo impianto: K220 2V (brewhouse da 220 L, batch 180 L) con 3 UT-200 PRO a rotazione, acqua calda separata per lo sparge e CIP kit manuale. Una cotta a settimana a regime: ≈ 46 cotte e ≈ 83 hl di produzione all'anno (vedi foglio Cadenza produzione).
A26: ="• Nei primi anni si vende meno ("&ROUND(Parametri!C39*100,0)&"%, "&ROUND(Parametri!C40*100,0)&"%, "&ROUND(Parametri!C41*100,0)&"% del volume a regime) e la cotta non è settimanale; dal quarto anno si va a regime con circa "&ROUND(Parametri!C22,0)&" fusti da "&Parametri!C21&" L al mese ("&ROUND(Parametri!C22*Parametri!C21,-1)&" L): obiettivo da verificare con preordini ed eventi prima di investire." -> • Nei primi anni si vende meno (40%, 65%, 85% del volume a regime) e la cotta non è settimanale; dal quarto anno si va a regime con circa 12 fusti da 30 L al mese (360 L): obiettivo da verificare con preordini ed eventi prima di investire.
A27: ="• Il locale è da verificare (Checklist locale) e la quota lavori in Parametri cambia l'investimento. "&IF(Parametri!C77=0,"L'INPS è a 0 perché entrambi avete un altro lavoro: va verificata (la riga 22 mostra cosa succede se è dovuta).","L'INPS è calcolata per "&Parametri!C77&" persone (Parametri riga 66): verificare con commercialista/INPS se è davvero dovuta.") -> • Il locale è da verificare (Checklist locale) e la quota lavori in Parametri cambia l'investimento. L'INPS è a 0 perché entrambi avete un altro lavoro: va verificata (la riga 22 mostra cosa succede se è dovuta).
A28: • Prezzi dei macchinari letti sul sito BrewTaurus; molte voci di contorno sono stime mie (colonna Tipo = S). Una soluzione PRO (brewhouse BH-150/BH-400) richiede preventivo: i prezzi non sono pubblici.
A29: • Il mutuo (Parametri, sezione 8) è inserito nel Business plan dalla riga 60. Le righe 5–23 qui sopra mostrano l'attività senza mutuo; le righe 32–41 mostrano la situazione con il mutuo.
A31: Con mutuo (Parametri, sezione 8)
A32: Importo del mutuo | B32: =Parametri!C101 -> 60311.691 | C32: Quota finanziata e importo si impostano in Parametri righe 88–89
A33: Capitale proprio da versare | B33: ='Impianto e costi'!G73-Parametri!C101 -> 0 | C33: Investimento totale − mutuo
A34: Rata annua dopo il preammortamento | B34: =Parametri!C106 -> 8403.2385 | C34: Durata e tasso in Parametri righe 91–93
A35: Interessi totali pagati sul mutuo | B35: ='Business plan'!B78 -> 27942.512 | C35: Costo del finanziamento su tutta la durata
A36: Copertura del debito minima | B36: =IF(COUNT('Business plan'!C72:Q72)=0,"n/d",MIN('Business plan'!C72:Q72)) -> 0.24053449 | C36: Sotto 1,0x la gestione non basta a pagare le rate e i soci devono versare cassa. Le banche guardano di solito valori ben sopra 1 (indicativo)
A37: Flusso di cassa dopo le rate – anno 1 | B37: ='Business plan'!C71 -> -3206.3254 | C37: Negativo = fabbisogno di cassa dei soci
A38: Flusso di cassa dopo le rate – anno 3 | B38: ='Business plan'!E71 -> 75.142451
A39: Flusso di cassa dopo le rate – anno 5 | B39: ='Business plan'!G71 -> 1894.7691 | C39: Dipende dalla durata del mutuo (Parametri riga 103): se è già finito, la rata non c'è più
A40: Esborso massimo cumulato dei soci (picco) | B40: ='Business plan'!B77 -> 6381.0416 | C40: Capitale proprio più eventuali versamenti negli anni deboli
A41: Payback dei soci (anni per recuperare capitale proprio e versamenti) | B41: ='Business plan'!B76 -> 6.393386 | C41: Se il mutuo copre tutto, il capitale proprio è 0 e conta l'esborso di cassa nei primi anni

Sheet Mercato
A1: Analisi di mercato – birra artigianale in Italia
A2: Dati da Assobirra Annual Report 2025, Unionbirrai e fonti di settore citate in Fonti. Prezzi: indicativi.
A4: Indicatore | B4: Valore | C4: Unità | D4: Fonte / nota
A5: Consumi di birra in Italia 2025 | B5: 21.2 | C5: milioni hl | D5: Assobirra Annual Report 2025 (−2,5% sul 2024)
A6: Produzione di birra in Italia 2025 | B6: 16.8 | C6: milioni hl | D6: Assobirra (−2,5% sul 2024)
A7: Consumo pro capite 2024 | B7: 36.4 | C7: L/anno | D7: Assobirra Annual Report 2024
A8: Birrifici artigianali attivi 2025 | B8: 1008 | C8: n | D8: Assobirra: 1.008 (1.007 nel 2024)
A9: Produzione artigianale 2025 | B9: 470000 | C9: hl | D9: Assobirra (480.000 nel 2024)
A10: Quota di mercato artigianale (volume) 2025 | B10: 0.022 | C10: % | D10: Assobirra (2,3% nel 2024); oltre il 20% in valore (businessonline.it)
A11: Segmento analcolico/low-alcol 2025 | B11: 0.0389 | C11: % | D11: Assobirra: quota raddoppiata da 2,1% a 3,9%
A12: Addetti nei birrifici artigianali 2025 | B12: 3120 | C12: n | D12: Assobirra / Cronache di Birra
A13: Produzione media per birrificio artigianale | B13: =B9/B8 -> 466.26984 | C13: hl/anno | D13: Calcolato: 470.000 hl ÷ 1.008. La mediana è molto più bassa: la maggior parte dei birrifici produce poche centinaia di hl.
A15: Prezzi di riferimento | B15: Min | C15: Max | D15: Fonte / nota
A16: Fusto 20–30 L all'ingrosso Horeca (€/L) | B16: 3 | C16: 5 | D16: ilmiobusinessplan.com; softwarebusinessplan.it
A17: Birra alla spina nel locale (€/L) | B17: 6 | C17: 12 | D17: ilmiobusinessplan.com
A18: Bottiglia artigianale in negozio specializzato, 33 cl (€) | B18: 4 | C18: 6 | D18: La Casetta Craft Beer Crew
A19: Prezzo medio al litro canale Horeca (€/L) | B19: 10 | C19: 10 | D19: La Casetta Craft Beer Crew (retail ≈3 €/L)
A20: Fusto 20 L venduto online al consumatore, IVA inclusa (€) | B20: 89 | C20: 160 | D20: Birra Cocca Mia, Birra Flea 89 €; Birrificio Caligola 160 € (saporitipicipiemontesi.it)
A22: Lettura del mercato
A23: • Mercato maturo e in leggero calo: consumi totali −2,5% nel 2025. La birra artigianale tiene (quota stabile ≈2,2% a volume ma oltre il 20% a valore), ma non cresce.
A24: • Offerta affollata: oltre 1.000 birrifici artigianali per 470.000 hl. In media meno di 500 hl a birrificio: un impianto da pochi ettolitri/anno è una nicchia, spesso integrata in un'altra attività.
A25: • Margine: il prezzo al litro artigianale (3–5 €/L ingrosso, 6–12 €/L alla spina) è molto sopra l'industriale (circa 3 €/L al retail), ma richiede brand, qualità costante e vendita diretta.
A26: • Segmenti in crescita: analcolico/low-alcol (≈3,9% del mercato) e prodotti locali/di territorio. Un'offerta di birre leggere e bevibili è coerente con la domanda.
A27: ="• Canali: pub, ristoranti, enoteche, beer shop, mercati, eventi, vendita diretta e taproom. Il fusto è il canale principale ("&ROUND(Parametri!C26*100,0)&"% del volume nel modello) ma ha il prezzo più basso." -> • Canali: pub, ristoranti, enoteche, beer shop, mercati, eventi, vendita diretta e taproom. Il fusto è il canale principale (80% del volume nel modello) ma ha il prezzo più basso.
A28: • Rischi: prezzo (concorrenza di marchi industriali e altri artigianali), costi di energia e materie prime, stagionalità, logistica e crediti verso i locali.
A29: • Prima di investire: mappare i locali e i concorrenti entro 50–80 km, fare assaggi e preordini, e chiedere ai primi 5–10 clienti volumi e prezzi reali.
A31: SWOT sintetica
A32: Punti di forza | B32: Debolezze | C32: Opportunità | D32: Minacce
A33: Impianto moderno BrewTaurus (acciaio, glicole, pressione); costi iniziali contenuti rispetto a un impianto da 10 hl | B33: Capacità limitata (circa 80 hl/anno con 3 fermentatori); investimento elevato rispetto ai ricavi: il rientro dipende dai volumi venduti | C33: Birre leggere/NoLo, prodotti di territorio, vendita diretta e taproom | D33: Mercato maturo e stagnante; concorrenza di oltre 1.000 birrifici
A34: Controllo totale su ricette e qualità; possibilità di scalare con altri tank | B34: Poco tempo disponibile: entrambi avete un altro lavoro; dipendenza da voi due | C34: Fidelizzazione di ristoranti e locali con rotazione fusti | D34: Aumento dei costi di energia e materie prime
A35: Accisa ridotta per microbirrifici sotto i 10.000 hl | B35: Pre-order e consegne non immediate; documenti PED da verificare per l'uso commerciale | C35: Eventi, collaborazioni con aziende agricole e hotel | D35: Burocrazia e tempi di autorizzazione (ASL, ADM)

Sheet Normativa e fisco
A1: Normativa italiana e fiscalità – adempimenti per aprire un birrificio
A2: Sintesi informativa basata su fonti pubbliche citate in Fonti. Non è consulenza legale/fiscale: verificare con commercialista, SUAP, ASL e ADM.
A4: Adempimento | B4: Ente | C4: Cosa prevede | D4: Tempi indicativi | E4: Costo stimato (€) | F4: Note e verifiche
A5: Partita IVA e codice ATECO | B5: Agenzia delle Entrate | C5: Apertura P.IVA con ATECO 11.05.00 (Produzione di birra); scelta ditta individuale/SRL/SAS | D5: Pochi giorni | E5: 0–300 (+ notaio per SRL) | F5: Prima di ogni altra pratica
A6: Iscrizione al Registro Imprese e INPS | B6: Camera di Commercio / INPS | C6: ComUnica telematica; iscrizione alla gestione artigiani/commercianti | D6: Pochi giorni | E6: ≈100–300 | F6: Contributi INPS minimi a carico del titolare
A7: SCIA di avvio attività | B7: SUAP del Comune | C7: Segnalazione certificata di inizio attività produttiva (e di vendita al dettaglio se prevista) | D7: Immediata dopo la presentazione; verifiche successive | E7: ≈100–500 | F7: Verificare destinazione d'uso e agibilità del locale
A8: Notifica sanitaria / registrazione stabilimento | B8: ASL | C8: Registrazione dello stabilimento alimentare (Reg. CE 852/2004); sopralluogo | D8: 1–3 mesi (La Casetta Craft Beer Crew) | E8: 500–2.000 | F8: Locale con pavimenti/pareti lavabili, scarichi, spogliatoio e servizi igienici
A9: Piano HACCP e tracciabilità | B9: ASL / consulente | C9: Autocontrollo (HACCP) e tracciabilità di materie prime e lotti (Reg. CE 178/2002) | D9: Prima dell'avvio | E9: ≈900 | F9: Registro lotti, pulizie, temperature
A10: Etichettatura | B10: Reg. UE 1169/2011 | C10: Denominazione, volume, titolo alcolometrico, lotto, TMC, indicazione degli allergeni, dati dell'operatore, ecc. | D10: Prima della vendita | E10: Grafica nei costi di avvio | F10: Verificare con un consulente quali indicazioni sono obbligatorie per le bevande alcoliche
A11: Licenza fiscale / deposito fiscale | B11: Agenzia delle Dogane e dei Monopoli (ADM) | C11: Autorizzazione come deposito fiscale/microbirrificio, codice accisa, verifica tecnica degli impianti, registri di carico e scarico, dichiarazioni periodiche | D11: Alcuni mesi | E11: 1.000–2.000 (La Casetta) | F11: La cauzione è calcolata da ADM sulla capacità dei serbatoi e sul prodotto che si intende detenere in sospensione di accisa
A12: Accisa sulla birra | B12: ADM | C12: €2,98 per ettolitro e per grado Plato nel 2026–2027; si paga all'immissione in consumo | D12: Mensile (dichiarazioni) | E12: Calcolata nel modello | F12: Riduzione per microbirrifici ≤10.000 hl: 40% o 50% a seconda della fonte (vedi Parametri); semplificazioni per i piccolissimi
A13: Definizione di birra artigianale | B13: L. 154/2016 (e decreti attuativi) | C13: Piccolo birrificio indipendente, ≤200.000 hl/anno, birra non pastorizzata né microfiltrata | D13: — | E13: — | F13: Rilevante per l'accisa ridotta e per la dicitura 'artigianale'
A14: Antincendio | B14: Vigili del Fuoco | C14: CPI solo se l'attività supera soglie di legge; in ogni caso estintori e valutazione dei rischi | D14: Dipende | E14: ≈600 (stima) | F14: Chiedere al tecnico
A15: Sicurezza sul lavoro | B15: Normativa D.Lgs. 81/2008 | C15: Valutazione rischi, formazione, eventuale RSPP se ci sono dipendenti | D15: Prima dell'avvio | E15: Da preventivare | F15: Valido anche per chi lavora in famiglia/ditta
... A18: Trasporto di prodotti sottoposti ad accisa | B18: ADM | C18: Documenti di accompagnamento per merce sotto accisa o in sospensione | D18: Per spedizione | E18: — | F18: Chiedere al commercialista/ADM
A20: Imposte e regime fiscale
A21: Voce | B21: Regime | C21: Aliquota/regola | F21: Note
A22: IVA | B22: Tutti | C22: 22% sulla vendita di birra (aliquota ordinaria) | F22: Acquisti con IVA detraibile solo in regime ordinario
A23: Imposta sostitutiva | B23: Forfettario (ditta individuale) | C23: 15% (5% per i primi 5 anni se requisiti); base imponibile = ricavi × coefficiente 40% − contributi INPS | F23: Limite ricavi 85.000 € (verificare); l'IVA sugli acquisti non è detraibile; niente IRAP
A24: IRES | B24: SRL | C24: 24% sull'utile | F24: Più oneri amministrativi (bilancio, notaio)
A25: IRAP | B25: SRL | C25: 3,9% base (varia per regione) | F25: Nel modello è applicata sull'EBIT come semplificazione
A26: Accisa | B26: Tutti | C26: 2,98 €/hl/°P, con riduzione per microbirrifici | F26: Vedi Parametri per la riduzione usata
A27: INPS 2026 | B27: Artigiani (titolare e coadiuvanti) | C27: Minimale 18.808 €; contributo fisso 4.521,36 € a persona; 24% sul reddito oltre il minimale fino a 56.224 €; riduzione 35% per i forfettari su richiesta | F27: Circolare INPS 14/2026. Nel modello l'INPS è calcolato per ciascuna persona
A28: Due persone: familiari | B28: Ditta individuale + impresa familiare | C28: Se il secondo è un familiare (coniuge, parenti/affini entro i gradi di legge) può essere coadiuvante: il forfettario resta applicabile, l'imposta sostitutiva è dovuta dal titolare sull'intero reddito, il coadiuvante versa i propri contributi INPS | F28: Limite di 20.000 € di spese per lavoro nel forfettario (pmi.it). Verificare con commercialista
A29: Due persone: non familiari | B29: SNC / SAS / SRL | C29: Il forfettario non è applicabile alle società: IRPEF sui soci (snc/sas) oppure IRES+IRAP (SRL); i soci che lavorano versano l'INPS | F29: Scelta: SRL, quindi nel modello regime 2 (IRES + IRAP)
A30: SRL: adempimenti | B30: Notaio / Registro Imprese | C30: Atto costitutivo notarile, deposito annuale del bilancio, diritto annuale alla Camera di Commercio, capitale sociale minimo (verificare importo) | F30: Gli amministratori compensati versano alla gestione separata INPS; chiarire con il commercialista. Con un altro lavoro l'obbligo INPS artigiani può non scattare
A32: Agevolazioni e finanziamenti (controllati a ottobre 2026: da confermare con commercialista ed enti)
A33: • Autoimpiego Centro-Nord (Invitalia, under 35, fondo perduto): richiede disoccupazione/inattività o condizioni simili. Con un altro lavoro probabilmente non spetta: verificare.
A34: • Piemonte, Finpiemonte (L.R. 32/23 Autoimpiego): 70% a tasso zero e 30% a tasso bancario per macchinari e impianti; i requisiti sulla condizione lavorativa dei soci vanno verificati.
A35: • Nuova Sabatini: contributo sugli interessi, solo beni nuovi, finanziamenti da 20.000 €, durata massima 5 anni.
A36: • Fondo di Garanzia PMI: garanzia fino all'80% sui finanziamenti per investimenti, gratuita per le microimprese, richiesta tramite banca o Confidi.
A37: • Bandi camerali e credito d'imposta o ammortamenti agevolati per beni strumentali: solo con commercialista, in base al regime.

Sheet Parametri
A1: Parametri e ipotesi del modello
A2: Blu = ipotesi modificabili; nero = formule; verde = collegamenti ad altri fogli. Tutti i prezzi sono IVA esclusa e in euro reali (senza inflazione).
A4: Parametro | B4: Unità | C4: Valore | D4: Fonte / nota
A5: 1. Scenari impianto (capacità produttiva)
A6: Nome scenario | C6: K220 2V + 3×UT-200 | D6: Impianto scelto: una cotta a settimana nel K220 2V (acqua calda separata, CIP kit manuale), 3 fermentatori UT-200 PRO (PED) a rotazione
A7: Volume di una cotta (netto nel fermentatore) | B7: L | C7: 180 | D7: K220 2V: 150–190 L (scelgo 180). I UT-200 hanno 200 L effettivi
A8: Numero fermentatori | B8: n | C8: 3 | D8: Una cotta a settimana, ~2 settimane di fermentazione + maturazione/pulizia: servono 3 tank a rotazione
A9: Occupazione del tank per ciclo (fermentazione + maturazione + pulizia) | B9: giorni | C9: 21 | D9: 2 settimane di fermentazione + circa 1 settimana tra raffreddamento, confezionamento e CIP. Per le lager serve di più
A10: Utilizzo massimo dei tank nell'anno | B10: % | C10: 0.9 | D10: Stima mia: fermate, pulizie, ritardi
A11: Cotte a settimana (massimo) | B11: n | C11: 1 | D11: Una cotta a settimana (di solito nel weekend)
A12: Settimane di produzione all'anno | B12: sett. | C12: 46 | D12: Esclude ferie e fermate
A13: Cotte/anno consentite dai tank | B13: n | C13: =C8*365*C10/C9 -> 46.928571 | D13: Calcolo: n. tank × 365 × utilizzo ÷ giorni per ciclo
A14: Cotte/anno consentite dalla sala cottura | B14: n | C14: =C11*C12 -> 46
A15: Cotte/anno (minimo dei due limiti) | B15: n | C15: =ROUND(MIN(C13,C14),0) -> 46
A16: Capacità produttiva annua | B16: L | C16: =C15*C7 -> 8280
A17: Capacità produttiva annua | B17: hl | C17: =C16/100 -> 82.8
A18: 2. Vendite
A19: Fusti venduti all'anno (a regime) | B19: fusti/anno | C19: 144 | D19: Scelta vostra: al posto del mix 80/20. 200 fusti da 30 L = circa 17 al mese. L'obiettivo dichiarato oggi è 8–10 al mese (≈ 100–120 all'anno): da verificare con preordini ed eventi prima di investire. Nei primi anni si vende meno (percentuali sotto)
A20: Bottiglie vendute all'anno (a regime) | B20: bottiglie/anno | C20: 3300 | D20: Scelta vostra: al posto del mix 80/20. 4.550 bottiglie da 33 cl = circa 1.500 L, un quinto del volume. Il totale (fusti + bottiglie) non può superare la capacità dell'impianto: vedi il controllo più sotto
A21: Capacità del fusto | B21: L | C21: 30 | D21: Fusti inox da 30 L (scelta vostra)
A22: ="Fusti da "&C21&" L venduti al mese (media a regime)" -> Fusti da 30 L venduti al mese (media a regime) | B22: n/mese | C22: =C19/12 -> 12 | D22: Calcolato: fusti all'anno ÷ 12
A23: Volume venduto in fusti a regime | B23: L/anno | C23: =C19*C21 -> 4320 | D23: Fusti all'anno × capacità del fusto
A24: Volume venduto in bottiglia a regime | B24: L/anno | C24: =C20*C38 -> 1089 | D24: Bottiglie all'anno × volume della bottiglia
A25: Volume venduto a regime (domanda) | B25: L/anno | C25: =C23+C24 -> 5409 | D25: Fusti + bottiglie, in litri
A26: Quota volume venduta in fusti | B26: % | C26: =IF(C25=0,0,C23/C25) -> 0.79866889 | D26: Calcolata dai volumi sopra (non è più un'ipotesi: serve per costi e ricavi)
A27: Quota volume venduta in bottiglia | B27: % | C27: =1-C26 -> 0.20133111 | D27: Calcolata
A28: Perdite di processo e campioni | B28: % | C28: 0.04 | D28: Stima mia: trub, linee, campionature, invenduto
A29: Capacità venduta all'anno (a regime) | B29: L/anno | C29: =C16*(1-C28) -> 7948.8 | D29: ="Capacità produttiva di tank e sala cottura (riga 16: "&C8&" fermentatori, "&C9&" giorni per ciclo tra fermentazione, maturazione e pulizia, "&ROUND(C10*100,0)&"% di utilizzo) meno le perdite di processo" -> Capacità produttiva di tank e sala cottura (riga 16: 3 fermentatori, 21 giorni per ciclo tra fermentazione, maturazione e pulizia, 90% di utilizzo) meno le perdite di processo
A30: Capacità massima al mese (media a regime) | B30: L/mese | C30: =C29/12 -> 662.4 | D30: ="Circa "&ROUND(C30/C21,0)&" fusti da "&C21&" L al mese se tutto fosse in fusti. Nel singolo mese dipende da quante cotte cadono (3–5)" -> Circa 22 fusti da 30 L al mese se tutto fosse in fusti. Nel singolo mese dipende da quante cotte cadono (3–5)
A31: Domanda al mese (media a regime) | B31: L/mese | C31: =C25/12 -> 450.75 | D31: Fusti e bottiglie indicati sopra, divisi per 12
A32: Utilizzo della capacità a regime | B32: % | C32: =IF(C29=0,0,C25/C29) -> 0.68048007 | D32: Oltre 100% = la domanda supera quello che l'impianto può produrre
A33: Controllo capacità | C33: =IF(C25<=C29,"OK","SUPERATA") -> OK | D33: =IF(C25<=C29,"La domanda a regime rientra nella capacità: margine di "&ROUND(C29-C25,0)&" L all'anno","Domanda oltre la capacità: il modello vende solo "&ROUND(C29,0)&" L all'anno invece di "&ROUND(C25,0)&". Riducete fusti o bottiglie, oppure aggiungete fermentatori o cotte") -> La domanda a regime rientra nella capacità: margine di 2540 L all'anno
A34: Fusti massimi all'anno con le bottiglie indicate | B34: fusti/anno | C34: =MAX(0,(C29-C24)/C21) -> 228.66 | D34: Quanti fusti entrano nella capacità, lasciando alle bottiglie il volume indicato
A35: Bottiglie massime all'anno con i fusti indicati | B35: bottiglie/anno | C35: =MAX(0,(C29-C23)/C38) -> 10996.364 | D35: Quante bottiglie entrano nella capacità, lasciando ai fusti il volume indicato
A36: Prezzo fusti (IVA esclusa, accisa inclusa) | B36: €/L | C36: 4 | D36: Fusti per eventi e feste a privati: 89–160 € IVA inclusa per 20 L (birrifici online) ≈ 3,65–6,5 €/L senza IVA. Uso 4,00 (≈ 98 € per un fusto da 20 L, ≈ 146 € da 30 L, IVA inclusa). Pub: 3–5 €/L
A37: Prezzo bottiglia 33 cl (IVA esclusa, accisa inclusa) | B37: €/bottiglia | C37: 2 | D37: Stima mia: in negozio specializzato 4–6 € a 33 cl (La Casetta Craft Beer Crew); all'ingrosso circa 2–3 €
A38: Volume della bottiglia | B38: L | C38: 0.33 | D38: Bottiglia da 33 cl
A39: Domanda raggiunta – anno 1 (% del volume a regime) | B39: % | C39: 0.4 | D39: Stima mia: i primi anni si vende meno
A40: Domanda raggiunta – anno 2 | B40: % | C40: 0.65
A41: Domanda raggiunta – anno 3 | B41: % | C41: 0.85
...

Sheet Cadenza produzione
A1: Cadenza produttiva: una cotta a settimana con 3 fermentatori
A2: Ogni cotta riempie un fermentatore; il tank resta occupato circa 3 settimane (2 di fermentazione + 1 tra raffreddamento, confezionamento e CIP).
A4: Tank | B4: Sett. 1 | C4: Sett. 2 | D4: Sett. 3 | E4: Sett. 4 | F4: Sett. 5 | G4: Sett. 6 | H4: Sett. 7 | I4: Sett. 8 | J4: Sett. 9 | K4: Sett. 10 | L4: Sett. 11 | M4: Sett. 12
A5: Tank 1 | B5: R | C5: F | D5: F | E5: M | F5: R | G5: F | H5: F | I5: M | J5: R | K5: F | L5: F | M5: M
A6: Tank 2 | C6: R | D6: F | E6: F | F6: M | G6: R | H6: F | I6: F | J6: M | K6: R | L6: F | M6: F
A7: Tank 3 | D7: R | E7: F | F7: F | G7: M | H7: R | I7: F | J7: F | K7: M | L7: R | M7: F
A9: Legenda: R = cotta e riempimento (giorno 1); F = fermentazione (circa 14 giorni); M = maturazione, raffreddamento, confezionamento e CIP (circa 1 settimana).
A10: Con 2 settimane di fermentazione un tank è libero dopo circa 3 settimane: servono 3 tank per una cotta a settimana. Con 2 soli tank non c'è margine per pulizie e ritardi.
A12: Carico a regime | B12: Valore | C12: Unità | D12: Come si calcola
A13: Litri per cotta | B13: =Parametri!$C$7 -> 180 | C13: L | D13: Parametri
A14: Cotte all'anno (limite dei tank) | B14: =Parametri!$C$15 -> 46 | C14: n | D14: Dai Parametri: 3 tank × 365 × utilizzo ÷ 21 giorni
A15: Produzione annua a regime | B15: =Parametri!$C$17 -> 82.8 | C15: hl | D15: Capacità produttiva
A16: Venduto a regime (domanda) | B16: =Parametri!$C$25/100 -> 54.09 | C16: hl | D16: Da fusti e bottiglie all'anno indicati
A17: Litri venduti per cotta | B17: =B13*(1-Parametri!$C$28) -> 172.8 | C17: L | D17: Dopo le perdite
A18: ="Fusti da "&Parametri!C21&" L per cotta" -> Fusti da 30 L per cotta | B18: =B17*Parametri!$C$26/Parametri!$C$21 -> 4.6003328 | C18: n | D18: ="Quota fusti: "&ROUND(Parametri!C26*100,0)&"%" -> Quota fusti: 80%
A19: Bottiglie da 33 cl per cotta | B19: =B17*Parametri!$C$27/Parametri!$C$38 -> 105.42429 | C19: n | D19: ="Quota bottiglie: "&ROUND(Parametri!C27*100,0)&"%" -> Quota bottiglie: 20%
A20: Ore di lavoro per cotta (stima) | B20: =Parametri!$C$91+B17/100*Parametri!$C$92 -> 14.32 | C20: ore | D20: Cotta e pulizie + confezionamento, consegne e vendite
A21: Ore a settimana in due (cotta ogni settimana) | B21: =B20 -> 14.32 | C21: ore | D21: Da confrontare con 20–30 ore a settimana disponibili tra voi due

Sheet Impianto e costi
A1: Impianto completo: elenco, specifiche e costi
A2: Impianto scelto: K220 2V + 3×UT-200 PRO. Tipo: V = prezzo letto sul sito BrewTaurus; N = non verificato sul sito; S = stima mia. Prezzi IVA esclusa salvo diversa indicazione.
A4: # | B4: Voce | C4: Dettaglio / specifiche | D4: Tipo | E4: K220 Q.tà | F4: K220 Prezzo | G4: K220 Totale | H4: Note / link
A5: A. Macchinari principali (BrewTaurus)
A6: 1 | B6: Brewhouse | C6: K220 2V: mash tun + boil kettle da 225 L, 7 kW, 2 pompe MP40, counterflow chiller, batch 150–190 L. Senza HLT: lo sparge richiede acqua calda separata | D6: V | E6: 1 | F6: 6999 | G6: =E6*F6 -> 6999 | H6: Prezzo letto sul sito
A7: 2 | B7: Fermentatori | C7: UT-200 PRO 200/260 L, 2,0 bar, PED Modulo H con dichiarazione di conformità per vaso, racking arm + spunding + pietra carbonatrice inclusi, camicia glicole. Servono 3 tank a rotazione per una cotta a settimana | D7: V | E7: =Parametri!$C$8 -> 3 | F7: 4490 | G7: =E7*F7 -> 13470 | H7: UT-200 4.490 € letto sul sito; su ordinazione (preventivo in 2 giorni)
A8: 3 | B8: Chiller glicole | C8: Quantor Chilly 25 M-LT 2,2 kW (scelto prudenzialmente per 3 tank da 200 L) | D8: V | E8: 1 | F8: 5349 | G8: =E8*F8 -> 5349 | H8: Prezzo letto sul sito. Voi lo comprereste usato: confermare la potenza con BrewTaurus
A9: 4 | B9: Collegamento glicole ai tank | C9: Tubo isolato, manifold mandata/ritorno e raccordi verso Ø31,8 mm TC dei tank | D9: S | E9: 1 | F9: 500 | G9: =E9*F9 -> 500 | H9: Stima mia
A10: 5 | B10: Impianto CIP | C10: CIP kit manuale (pompa 65 W, spray head rotante, raccordi TC): lavaggio in ricircolo con detergente e sanitizzante; l'acqua calda va preparata a parte | D10: V | E10: 1 | F10: 499 | G10: =E10*F10 -> 499 | H10: CIP kit 499 € letto sul sito
A11: 6 | B11: Hose Kit | C11: Tubo silicone alimentare alta temperatura 2 m + quick disconnect + raccordi 1.5" TC | D11: V | E11: 4 | F11: 109 | G11: =E11*F11 -> 436 | H11: Il K220 ha già molti raccordi: 4 è una stima
A12: 7 | B12: Controllo temperatura fermentatori | C12: Controller digitale + valvola glicole per ciascun tank | D12: S | E12: =Parametri!$C$8 -> 3 | F12: 130 | G12: =E12*F12 -> 390 | H12: Stima mia (Inkbird ITC-308 WiFi costa 79 €)
A13: 8 | B13: Quadro elettrico e controllo sala cottura | C13: Armadio IP54/65, sezionatore, magnetotermici/differenziali, SSR/contattori, PID/PLC, PT100, 24 V, pulsanti, emergenza, cablaggio (da far fare all'elettricista) | D13: S | E13: 1 | F13: 1200 | G13: =E13*F13 -> 1200 | H13: Stima mia: da verificare se il controller è incluso nel K220 2V
A14: 9 | B14: Counterflow chiller (se non incluso) | C14: Scambiatore mosto | D14: V | E14: 0 | F14: 0 | G14: =E14*F14 -> 0 | H14: Incluso nel K220 2V
A15: 10 | B15: Serbatoio acqua calda per sparge | C15: Con il K220 2V manca l'HLT: serve una fonte di acqua calda separata per lo sparge | D15: S | E15: 1 | F15: 250 | G15: =E15*F15 -> 250 | H15: Stima mia
A16: 11 | B16: Trasporto macchinari da Praga | C16: Consegna dei macchinari (pallet) o ritiro con furgone: non incluso nei prezzi BrewTaurus. Per scaricare i tank servono carrello elevatore o gru | D16: S | E16: 1 | F16: 1200 | G16: =E16*F16 -> 1200 | H16: Stima mia, non verificata: chiedere a BrewTaurus un preventivo con trasporto incluso e confrontarlo con il ritiro vostro (distanza circa 1.000 km)
B17: Subtotale A | G17: =SUM(G6:G16) -> 30293
A19: B. Lavorazione, strumenti e magazzino
A20: 12 | B20: Mulino per malto a rulli | C20: Macina il malto in sala cottura (necessario se compri malto intero) | D20: S | E20: 1 | F20: 1300 | G20: =E20*F20 -> 1300 | H20: Stima mia: BrewTaurus vende mulini ma non ho letto il prezzo
A21: 13 | B21: Pompa di ricambio MP-40RM | C21: Pompa magnetica 65 W (ricambio): non acquistata, si compra se si rompe | D21: V | E21: 0 | F21: 0 | G21: =E21*F21 -> 0 | H21: Prezzo letto, a volte non disponibile
A22: 14 | B22: Strumenti di controllo qualità | C22: Densimetro/rifrattometro, pH-metro, termometri, bilancia di precisione, vetreria | D22: S | E22: 1 | F22: 400 | G22: =E22*F22 -> 400 | H22: Stima mia, versione snella: già avete qualche strumento
A23: 15 | B23: Analisi di laboratorio iniziali | C23: Grado alcolico, estratto, microbiologia sulle prime cotte | D23: S | E23: 1 | F23: 300 | G23: =E23*F23 -> 300 | H23: Stima mia, versione snella
A24: 16 | B24: Trattamento acqua | C24: Filtri a carbone (niente addolcitore) | D24: S | E24: 1 | F24: 300 | G24: =E24*F24 -> 300 | H24: Stima mia: scelta vostra; l'acqua del locale non è stata analizzata
A25: 17 | B25: Scaffalature, transpallet, carrelli | C25: Stoccaggio malto, confezioni, vuoti | D25: S | E25: 1 | F25: 400 | G25: =E25*F25 -> 400 | H25: Stima mia, versione snella (locale da 40–80 m²)
B26: Subtotale B | G26: =SUM(G20:G25) -> 2700
A28: ="C. Confezionamento in fusti ("&ROUND(Parametri!C26*100,0)&"% del volume)" -> C. Confezionamento in fusti (80% del volume)
A29: 18 | B29: ="Fusti inox "&Parametri!C21&" L" -> Fusti inox 30 L | C29: Numero = min(capacità, domanda) × quota fusti ÷ capacità del fusto ÷ giri annui, almeno 10 | D29: S | E29: =MAX(10,ROUNDUP(MIN(Parametri!$C$16,Parametri!$C$25)*Parametri!$C$26/Parametri!$C$21/Parametri!$C$60,0)) -> 21 | F29: =Parametri!$C$59 -> 110 | G29: =E29*F29 -> 2310 | H29: Prezzo del fusto = stima mia; possibile cauzione ai clienti
A30: 19 | B30: Raccordi/coupler per fusti | C30: Testine A/S per riempimento e prelievo | D30: S | E30: 2 | F30: 110 | G30: =E30*F30 -> 220 | H30: Stima mia
A31: 20 | B31: Sistema di riempimento e lavaggio fusti | C31: Postazione manuale con CO2 e CIP fusti | D31: S | E31: 1 | F31: 600 | G31: =E31*F31 -> 600 | H31: Stima mia
A32: 21 | B32: CO2: bombola, riduttore, manometri | C32: Bombola 10 kg + regolatore + linee | D32: S | E32: 1 | F32: 300 | G32: =E32*F32 -> 300 | H32: Stima mia
A33: 22 | B33: Cella frigorifera per fusti | C33: Stoccaggio fusti pieni a bassa temperatura, abbastanza grande da contenere i fusti in circolazione | D33: S | E33: 1 | F33: 5500 | G33: =E33*F33 -> 5500 | H33: Voi la volete: stima mia, abbastanza grande per i fusti in circolazione (usata costerebbe meno). Non è obbligatoria: la birra può restare nei tank e i fusti si riempiono a ordine
B34: Subtotale C | G34: =SUM(G29:G33) -> 8930
A36: ="D. Imbottigliamento ("&ROUND(Parametri!C27*100,0)&"% del volume)" -> D. Imbottigliamento (20% del volume)
A37: 23 | B37: Riempitrice a contropressione | C37: 4 teste, riempie dal tank in pressione | D37: S | E37: 1 | F37: 1200 | G37: =E37*F37 -> 1200 | H37: Stima mia, versione snella (valutare usato)
A38: 24 | B38: Capsulatrice | C38: Tappi corona | D38: S | E38: 1 | F38: 250 | G38: =E38*F38 -> 250 | H38: Stima mia
A39: 25 | B39: Etichettatrice manuale | C39: Etichette autoadesive applicate a mano | D39: S | E39: 1 | F39: 300 | G39: =E39*F39 -> 300 | H39: Stima mia, versione snella
A40: 26 | B40: Risciacquatrice e casse/tavoli | C40: Pulizia bottiglie e movimentazione | D40: S | E40: 1 | F40: 200 | G40: =E40*F40 -> 200 | H40: Stima mia, versione snella
B41: Subtotale D | G41: =SUM(G37:G40) -> 1950
A43: E. Locale, utenze e impianti
A44: 27 | B44: Pavimento con pendenze e pozzetti | C44: Scarico a pavimento, resina lavabile | D44: S | E44: 1 | F44: 2500 | G44: =E44*F44 -> 2500 | H44: Stima mia
A45: 28 | B45: Rivestimenti lavabili pareti e porte | C45: Requisito igienico-sanitario | D45: S | E45: 1 | F45: 600 | G45: =E45*F45 -> 600 | H45: Pareti e imbiancatura le fate voi: solo materiali (stima mia)
...

Sheet Materie prime
A1: Materie prime e ricette tipo
A2: Stime di consumo per stile e prezzi di acquisto. Da validare con ricette reali e preventivi dei fornitori.
A4: Stile | B4: Quota mix | C4: °Plato | D4: Malto (kg/hl) | E4: Prezzo malto (€/kg) | F4: Luppolo (g/hl) | G4: Prezzo luppolo (€/kg) | H4: Lievito (€/hl) | I4: Additivi/sali (€/hl) | J4: Costo malto (€/hl) | K4: Costo luppolo (€/hl) | L4: Costo totale (€/hl)
A5: Pils / Blonde (leggera, bevibile) | B5: 0.4 | C5: 12 | D5: 20 | E5: 1.3 | F5: 120 | G5: 35 | H5: 3 | I5: 1.5 | J5: =D5*E5 -> 26 | K5: =F5/1000*G5 -> 4.2 | L5: =J5+K5+H5+I5 -> 34.7
A6: Pale Ale / APA | B6: 0.35 | C6: 14 | D6: 23 | E6: 1.4 | F6: 300 | G6: 40 | H6: 4 | I6: 1.5 | J6: =D6*E6 -> 32.2 | K6: =F6/1000*G6 -> 12 | L6: =J6+K6+H6+I6 -> 49.7
A7: IPA (luppolata) | B7: 0.25 | C7: 16 | D7: 26 | E7: 1.5 | F7: 700 | G7: 45 | H7: 4.5 | I7: 1.5 | J7: =D7*E7 -> 39 | K7: =F7/1000*G7 -> 31.5 | L7: =J7+K7+H7+I7 -> 76.5
A9: Media pesata | B9: =SUM(B5:B7) -> 1 | C9: =SUMPRODUCT(B5:B7,C5:C7) -> 13.7 | L9: =SUMPRODUCT(B5:B7,L5:L7) -> 50.4
A10: Controllo: la quota mix deve fare 100%. Il costo medio per ettolitro va confrontato con i 30–60 €/hl citati da La Casetta Craft Beer Crew (variabile secondo ingredienti).
A12: Fabbisogno per una cotta dello scenario K220 (litri da Parametri)
A13: Stile | B13: Litri cotta | C13: Malto (kg) | D13: Malto (€) | E13: Luppolo (g) | F13: Luppolo (€) | G13: Lievito+additivi (€) | H13: Totale cotta (€) | I13: Costo materie prime (€/L)
A14: =A5 -> Pils / Blonde (leggera, bevibile) | B14: =Parametri!$C$7 -> 180 | C14: =D5*B14/100 -> 36 | D14: =C14*E5 -> 46.8 | E14: =F5*B14/100 -> 216 | F14: =E14/1000*G5 -> 7.56 | G14: =(H5+I5)*B14/100 -> 8.1 | H14: =D14+F14+G14 -> 62.46 | I14: =H14/B14 -> 0.347
A15: =A6 -> Pale Ale / APA | B15: =Parametri!$C$7 -> 180 | C15: =D6*B15/100 -> 41.4 | D15: =C15*E6 -> 57.96 | E15: =F6*B15/100 -> 540 | F15: =E15/1000*G6 -> 21.6 | G15: =(H6+I6)*B15/100 -> 9.9 | H15: =D15+F15+G15 -> 89.46 | I15: =H15/B15 -> 0.497
A16: =A7 -> IPA (luppolata) | B16: =Parametri!$C$7 -> 180 | C16: =D7*B16/100 -> 46.8 | D16: =C16*E7 -> 70.2 | E16: =F7*B16/100 -> 1260 | F16: =E16/1000*G7 -> 56.7 | G16: =(H7+I7)*B16/100 -> 10.8 | H16: =D16+F16+G16 -> 137.7 | I16: =H16/B16 -> 0.765
A18: Dove comprare e come acquistare (da verificare con preventivi)
A19: • Malto: sacchi da 25 kg o big bag, base pilsner 1,0–2,0 €/kg a seconda di quantità e fornitore (La Casetta Craft Beer Crew); malti speciali anche oltre 3 €/kg.
A20: • Luppolo: pellet in buste da 1 kg; varietà moderne (Citra, Mosaic, Nelson Sauvin) 6–8 € all'etto (La Casetta); varietà classiche 20–50 €/kg.
A21: • Lievito: secco o liquido; il lievito liquido costa di più (10–15 € a dose secondo ilmiobusinessplan.com).
A22: • Acqua: potenzialmente da addolcire/filtrare; correttivi (sali, acido lattico) tra gli additivi.
A23: • Detergenti: caustico (5–10 kg iniziali), acido (≈5 L), sanitizzante (1–2 L): sono compresi nella voce Detergenti dei Parametri.
A24: • Scorte: tenere circa 2 mesi di malto/luppolo; il malto va conservato asciutto, il luppolo in freezer.

Sheet Business plan
A1: Business plan a 15 anni – K220
A2: ="Scenario: "&Parametri!$C$6 -> Scenario: K220 2V + 3×UT-200
A4: Voce (valori reali, € salvo diversa indicazione) | B4: Anno 0 | C4: Anno 1 | D4: Anno 2 | E4: Anno 3 | F4: Anno 4 | G4: Anno 5 | H4: Anno 6 | I4: Anno 7 | J4: Anno 8 | K4: Anno 9 | L4: Anno 10 | M4: Anno 11 | N4: Anno 12 | O4: Anno 13 | P4: Anno 14 | Q4: Anno 15
A5: Domanda raggiunta (% del volume a regime) | C5: =Parametri!$C$39 -> 0.4 | D5: =Parametri!$C$40 -> 0.65 | E5: =Parametri!$C$41 -> 0.85 | F5: =Parametri!$C$42 -> 1 | G5: =Parametri!$C$43 -> 1 | H5: =Parametri!$C$43 -> 1 | I5: =Parametri!$C$43 -> 1 | J5: =Parametri!$C$43 -> 1 | K5: =Parametri!$C$43 -> 1 | L5: =Parametri!$C$43 -> 1 | M5: =Parametri!$C$43 -> 1 | N5: =Parametri!$C$43 -> 1 | ... Q5: =Parametri!$C$43 -> 1
A6: Capacità produttiva (L/anno) | C6: =Parametri!$C$16 -> 8280 | D6: =Parametri!$C$16 -> 8280 | E6: =Parametri!$C$16 -> 8280 | F6: =Parametri!$C$16 -> 8280 | G6: =Parametri!$C$16 -> 8280 | H6: =Parametri!$C$16 -> 8280 | I6: =Parametri!$C$16 -> 8280 | J6: =Parametri!$C$16 -> 8280 | ... Q6: =Parametri!$C$16 -> 8280
A7: Produzione (L): minimo tra capacità e domanda | C7: =MIN(C6,Parametri!$C$25*C5/(1-Parametri!$C$28)) -> 2253.75 | D7: =MIN(D6,Parametri!$C$25*D5/(1-Parametri!$C$28)) -> 3662.3438 | E7: =MIN(E6,Parametri!$C$25*E5/(1-Parametri!$C$28)) -> 4789.2188 | F7: =MIN(F6,Parametri!$C$25*F5/(1-Parametri!$C$28)) -> 5634.375 | G7: =MIN(G6,Parametri!$C$25*G5/(1-Parametri!$C$28)) -> 5634.375 | H7: =MIN(H6,Parametri!$C$25*H5/(1-Parametri!$C$28)) -> 5634.375 | I7: =MIN(I6,Parametri!$C$25*I5/(1-Parametri!$C$28)) -> 5634.375 | J7: =MIN(J6,Parametri!$C$25*J5/(1-Parametri!$C$28)) -> 5634.375 | ... Q7: =MIN(Q6,Parametri!$C$25*Q5/(1-Parametri!$C$28)) -> 5634.375
A8: Vendite (L, dopo le perdite) | C8: =C7*(1-Parametri!$C$28) -> 2163.6 | D8: =D7*(1-Parametri!$C$28) -> 3515.85 | E8: =E7*(1-Parametri!$C$28) -> 4597.65 | F8: =F7*(1-Parametri!$C$28) -> 5409 | G8: =G7*(1-Parametri!$C$28) -> 5409 | H8: =H7*(1-Parametri!$C$28) -> 5409 | I8: =I7*(1-Parametri!$C$28) -> 5409 | J8: =J7*(1-Parametri!$C$28) -> 5409 | ... Q8: =Q7*(1-Parametri!$C$28) -> 5409
A9: di cui in fusti (L) | C9: =C8*Parametri!$C$26 -> 1728 | D9: =D8*Parametri!$C$26 -> 2808 | E9: =E8*Parametri!$C$26 -> 3672 | F9: =F8*Parametri!$C$26 -> 4320 | G9: =G8*Parametri!$C$26 -> 4320 | H9: =H8*Parametri!$C$26 -> 4320 | I9: =I8*Parametri!$C$26 -> 4320 | J9: =J8*Parametri!$C$26 -> 4320 | ... Q9: =Q8*Parametri!$C$26 -> 4320
A10: di cui in bottiglia (L) | C10: =C8*Parametri!$C$27 -> 435.6 | D10: =D8*Parametri!$C$27 -> 707.85 | E10: =E8*Parametri!$C$27 -> 925.65 | F10: =F8*Parametri!$C$27 -> 1089 | G10: =G8*Parametri!$C$27 -> 1089 | H10: =H8*Parametri!$C$27 -> 1089 | I10: =I8*Parametri!$C$27 -> 1089 | J10: =J8*Parametri!$C$27 -> 1089 | ... Q10: =Q8*Parametri!$C$27 -> 1089
A11: Bottiglie vendute (n) | C11: =C10/Parametri!$C$38 -> 1320 | D11: =D10/Parametri!$C$38 -> 2145 | E11: =E10/Parametri!$C$38 -> 2805 | F11: =F10/Parametri!$C$38 -> 3300 | G11: =G10/Parametri!$C$38 -> 3300 | H11: =H10/Parametri!$C$38 -> 3300 | I11: =I10/Parametri!$C$38 -> 3300 | J11: =J10/Parametri!$C$38 -> 3300 | ... Q11: =Q10/Parametri!$C$38 -> 3300
A12: Cotte all'anno (n) | C12: =C7/Parametri!$C$7 -> 12.520833 | D12: =D7/Parametri!$C$7 -> 20.346354 | E12: =E7/Parametri!$C$7 -> 26.606771 | F12: =F7/Parametri!$C$7 -> 31.302083 | G12: =G7/Parametri!$C$7 -> 31.302083 | H12: =H7/Parametri!$C$7 -> 31.302083 | I12: =I7/Parametri!$C$7 -> 31.302083 | J12: =J7/Parametri!$C$7 -> 31.302083 | ... Q12: =Q7/Parametri!$C$7 -> 31.302083
A13: Utilizzo della capacità produttiva | C13: =IF(C6=0,0,C7/C6) -> 0.27219203 | D13: =IF(D6=0,0,D7/D6) -> 0.44231205 | E13: =IF(E6=0,0,E7/E6) -> 0.57840806 | F13: =IF(F6=0,0,F7/F6) -> 0.68048007 | G13: =IF(G6=0,0,G7/G6) -> 0.68048007 | H13: =IF(H6=0,0,H7/H6) -> 0.68048007 | I13: =IF(I6=0,0,I7/I6) -> 0.68048007 | J13: =IF(J6=0,0,J7/J6) -> 0.68048007 | ... Q13: =IF(Q6=0,0,Q7/Q6) -> 0.68048007
A14: RICAVI
A15: Ricavi fusti | C15: =C9*Parametri!$C$36 -> 6912 | D15: =D9*Parametri!$C$36 -> 11232 | E15: =E9*Parametri!$C$36 -> 14688 | F15: =F9*Parametri!$C$36 -> 17280 | G15: =G9*Parametri!$C$36 -> 17280 | H15: =H9*Parametri!$C$36 -> 17280 | I15: =I9*Parametri!$C$36 -> 17280 | J15: =J9*Parametri!$C$36 -> 17280 | ... Q15: =Q9*Parametri!$C$36 -> 17280
A16: Ricavi bottiglie | C16: =C11*Parametri!$C$37 -> 2640 | D16: =D11*Parametri!$C$37 -> 4290 | E16: =E11*Parametri!$C$37 -> 5610 | F16: =F11*Parametri!$C$37 -> 6600 | G16: =G11*Parametri!$C$37 -> 6600 | H16: =H11*Parametri!$C$37 -> 6600 | I16: =I11*Parametri!$C$37 -> 6600 | J16: =J11*Parametri!$C$37 -> 6600 | ... Q16: =Q11*Parametri!$C$37 -> 6600
A17: Ricavi totali (IVA esclusa) | C17: =C15+C16 -> 9552 | D17: =D15+D16 -> 15522 | E17: =E15+E16 -> 20298 | F17: =F15+F16 -> 23880 | G17: =G15+G16 -> 23880 | H17: =H15+H16 -> 23880 | I17: =I15+I16 -> 23880 | J17: =J15+J16 -> 23880 | ... Q17: =Q15+Q16 -> 23880
A18: COSTI VARIABILI
A19: Materie prime | C19: =C7/100*Parametri!$C$45 -> 1135.89 | D19: =D7/100*Parametri!$C$45 -> 1845.8212 | E19: =E7/100*Parametri!$C$45 -> 2413.7663 | F19: =F7/100*Parametri!$C$45 -> 2839.725 | G19: =G7/100*Parametri!$C$45 -> 2839.725 | H19: =H7/100*Parametri!$C$45 -> 2839.725 | I19: =I7/100*Parametri!$C$45 -> 2839.725 | J19: =J7/100*Parametri!$C$45 -> 2839.725 | ... Q19: =Q7/100*Parametri!$C$45 -> 2839.725
A20: Detergenti e sanitizzanti | C20: =C7/100*Parametri!$C$46 -> 90.15 | D20: =D7/100*Parametri!$C$46 -> 146.49375 | E20: =E7/100*Parametri!$C$46 -> 191.56875 | F20: =F7/100*Parametri!$C$46 -> 225.375 | G20: =G7/100*Parametri!$C$46 -> 225.375 | H20: =H7/100*Parametri!$C$46 -> 225.375 | I20: =I7/100*Parametri!$C$46 -> 225.375 | J20: =J7/100*Parametri!$C$46 -> 225.375 | ... Q20: =Q7/100*Parametri!$C$46 -> 225.375
A21: Energia elettrica | C21: =C7/100*Parametri!$C$48*Parametri!$C$49 -> 281.71875 | D21: =D7/100*Parametri!$C$48*Parametri!$C$49 -> 457.79297 | E21: =E7/100*Parametri!$C$48*Parametri!$C$49 -> 598.65234 | F21: =F7/100*Parametri!$C$48*Parametri!$C$49 -> 704.29688 | G21: =G7/100*Parametri!$C$48*Parametri!$C$49 -> 704.29688 | H21: =H7/100*Parametri!$C$48*Parametri!$C$49 -> 704.29688 | I21: =I7/100*Parametri!$C$48*Parametri!$C$49 -> 704.29688 | J21: =J7/100*Parametri!$C$48*Parametri!$C$49 -> 704.29688 | ... Q21: =Q7/100*Parametri!$C$48*Parametri!$C$49 -> 704.29688
A22: Acqua e fognatura | C22: =C7/100*Parametri!$C$50*Parametri!$C$51 -> 40.5675 | D22: =D7/100*Parametri!$C$50*Parametri!$C$51 -> 65.922188 | E22: =E7/100*Parametri!$C$50*Parametri!$C$51 -> 86.205938 | F22: =F7/100*Parametri!$C$50*Parametri!$C$51 -> 101.41875 | G22: =G7/100*Parametri!$C$50*Parametri!$C$51 -> 101.41875 | H22: =H7/100*Parametri!$C$50*Parametri!$C$51 -> 101.41875 | I22: =I7/100*Parametri!$C$50*Parametri!$C$51 -> 101.41875 | J22: =J7/100*Parametri!$C$50*Parametri!$C$51 -> 101.41875 | ... Q22: =Q7/100*Parametri!$C$50*Parametri!$C$51 -> 101.41875
A23: Imballaggi bottiglie (vetro, tappo, etichetta, cartone, CONAI) | C23: =C11*(Parametri!$C$52+Parametri!$C$53+Parametri!$C$54+Parametri!$C$55+Parametri!$C$56) -> 442.2 | D23: =D11*(Parametri!$C$52+Parametri!$C$53+Parametri!$C$54+Parametri!$C$55+Parametri!$C$56) -> 718.575 | E23: =E11*(Parametri!$C$52+Parametri!$C$53+Parametri!$C$54+Parametri!$C$55+Parametri!$C$56) -> 939.675 | F23: =F11*(Parametri!$C$52+Parametri!$C$53+Parametri!$C$54+Parametri!$C$55+Parametri!$C$56) -> 1105.5 | G23: =G11*(Parametri!$C$52+Parametri!$C$53+Parametri!$C$54+Parametri!$C$55+Parametri!$C$56) -> 1105.5 | H23: =H11*(Parametri!$C$52+Parametri!$C$53+Parametri!$C$54+Parametri!$C$55+Parametri!$C$56) -> 1105.5 | I23: =I11*(Parametri!$C$52+Parametri!$C$53+Parametri!$C$54+Parametri!$C$55+Parametri!$C$56) -> 1105.5 | J23: =J11*(Parametri!$C$52+Parametri!$C$53+Parametri!$C$54+Parametri!$C$55+Parametri!$C$56) -> 1105.5 | ... Q23: =Q11*(Parametri!$C$52+Parametri!$C$53+Parametri!$C$54+Parametri!$C$55+Parametri!$C$56) -> 1105.5
A24: Consumabili fusti (CO2, guarnizioni) | C24: =C9/100*Parametri!$C$57 -> 51.84 | D24: =D9/100*Parametri!$C$57 -> 84.24 | E24: =E9/100*Parametri!$C$57 -> 110.16 | F24: =F9/100*Parametri!$C$57 -> 129.6 | G24: =G9/100*Parametri!$C$57 -> 129.6 | H24: =H9/100*Parametri!$C$57 -> 129.6 | I24: =I9/100*Parametri!$C$57 -> 129.6 | J24: =J9/100*Parametri!$C$57 -> 129.6 | ... Q24: =Q9/100*Parametri!$C$57 -> 129.6
A25: Accisa sulla birra immessa in consumo | C25: =C8/100*Parametri!$C$47*Parametri!$C$62*(1-Parametri!$C$63) -> 529.9868 | D25: =D8/100*Parametri!$C$47*Parametri!$C$62*(1-Parametri!$C$63) -> 861.22855 | E25: =E8/100*Parametri!$C$47*Parametri!$C$62*(1-Parametri!$C$63) -> 1126.222 | F25: =F8/100*Parametri!$C$47*Parametri!$C$62*(1-Parametri!$C$63) -> 1324.967 | G25: =G8/100*Parametri!$C$47*Parametri!$C$62*(1-Parametri!$C$63) -> 1324.967 | H25: =H8/100*Parametri!$C$47*Parametri!$C$62*(1-Parametri!$C$63) -> 1324.967 | I25: =I8/100*Parametri!$C$47*Parametri!$C$62*(1-Parametri!$C$63) -> 1324.967 | J25: =J8/100*Parametri!$C$47*Parametri!$C$62*(1-Parametri!$C$63) -> 1324.967 | ... Q25: =Q8/100*Parametri!$C$47*Parametri!$C$62*(1-Parametri!$C$63) -> 1324.967
A26: Logistica e consegne | C26: =C17*Parametri!$C$58 -> 238.8 | D26: =D17*Parametri!$C$58 -> 388.05 | E26: =E17*Parametri!$C$58 -> 507.45 | F26: =F17*Parametri!$C$58 -> 597 | G26: =G17*Parametri!$C$58 -> 597 | H26: =H17*Parametri!$C$58 -> 597 | I26: =I17*Parametri!$C$58 -> 597 | J26: =J17*Parametri!$C$58 -> 597 | ... Q26: =Q17*Parametri!$C$58 -> 597
A27: Totale costi variabili | C27: =SUM(C19:C26) -> 2811.1531 | D27: =SUM(D19:D26) -> 4568.1237 | E27: =SUM(E19:E26) -> 5973.7002 | F27: =SUM(F19:F26) -> 7027.8826 | G27: =SUM(G19:G26) -> 7027.8826 | H27: =SUM(H19:H26) -> 7027.8826 | I27: =SUM(I19:I26) -> 7027.8826 | J27: =SUM(J19:J26) -> 7027.8826 | ... Q27: =SUM(Q19:Q26) -> 7027.8826
A28: Margine di contribuzione | C28: =C17-C27 -> 6740.8469 | D28: =D17-D27 -> 10953.876 | E28: =E17-E27 -> 14324.3 | F28: =F17-F27 -> 16852.117 | G28: =G17-G27 -> 16852.117 | H28: =H17-H27 -> 16852.117 | I28: =I17-I27 -> 16852.117 | J28: =J17-J27 -> 16852.117 | ... Q28: =Q17-Q27 -> 16852.117
A29: Margine di contribuzione % | C29: =IF(C17=0,0,C28/C17) -> 0.70570006 | D29: =IF(D17=0,0,D28/D17) -> 0.70570006 | E29: =IF(E17=0,0,E28/E17) -> 0.70570006 | F29: =IF(F17=0,0,F28/F17) -> 0.70570006 | G29: =IF(G17=0,0,G28/G17) -> 0.70570006 | H29: =IF(H17=0,0,H28/H17) -> 0.70570006 | I29: =IF(I17=0,0,I28/I17) -> 0.70570006 | J29: =IF(J17=0,0,J28/J17) -> 0.70570006 | ... Q29: =IF(Q17=0,0,Q28/Q17) -> 0.70570006
A30: COSTI FISSI
A31: Affitto locale | C31: =Parametri!$C$73*12 -> 0 | D31: =Parametri!$C$73*12 -> 0 | E31: =Parametri!$C$73*12 -> 0 | F31: =Parametri!$C$73*12 -> 0 | G31: =Parametri!$C$73*12 -> 0 | H31: =Parametri!$C$73*12 -> 0 | I31: =Parametri!$C$73*12 -> 0 | J31: =Parametri!$C$73*12 -> 0 | ... Q31: =Parametri!$C$73*12 -> 0
A32: Utenze fisse | C32: =Parametri!$C$74*12 -> 1440 | D32: =Parametri!$C$74*12 -> 1440 | E32: =Parametri!$C$74*12 -> 1440 | F32: =Parametri!$C$74*12 -> 1440 | G32: =Parametri!$C$74*12 -> 1440 | H32: =Parametri!$C$74*12 -> 1440 | I32: =Parametri!$C$74*12 -> 1440 | J32: =Parametri!$C$74*12 -> 1440 | ... Q32: =Parametri!$C$74*12 -> 1440
A33: Assicurazioni | C33: =Parametri!$C$75 -> 1500 | D33: =Parametri!$C$75 -> 1500 | E33: =Parametri!$C$75 -> 1500 | F33: =Parametri!$C$75 -> 1500 | G33: =Parametri!$C$75 -> 1500 | H33: =Parametri!$C$75 -> 1500 | I33: =Parametri!$C$75 -> 1500 | J33: =Parametri!$C$75 -> 1500 | ... Q33: =Parametri!$C$75 -> 1500
A34: Commercialista e consulenze | C34: =Parametri!$C$76 -> 500 | D34: =Parametri!$C$76 -> 500 | E34: =Parametri!$C$76 -> 500 | F34: =Parametri!$C$76 -> 500 | G34: =Parametri!$C$76 -> 500 | H34: =Parametri!$C$76 -> 500 | I34: =Parametri!$C$76 -> 500 | J34: =Parametri!$C$76 -> 500 | ... Q34: =Parametri!$C$76 -> 500
A35: Contributi INPS (tutte le persone che lavorano) | C35: =IF(Parametri!$C$77=0,0,Parametri!$C$77*(Parametri!$C$79*MIN(MAX(IF(Parametri!$C$64=1,C17*Parametri!$C$65,MAX(0,C28-(C31+C32+C33+C34+C36+C37+C38+C39+C40+C41)))/Parametri!$C$77,Parametri!$C$78),Parametri!$C$80)+Parametri!$C$81)*(1-IF(Parametri!$C$64=1,Parametri!$C$82,0))) -> 0 | D35: =IF(Parametri!$C$77=0,0,Parametri!$C$77*(Parametri!$C$79*MIN(MAX(IF(Parametri!$C$64=1,D17*Parametri!$C$65,MAX(0,D28-(D31+D32+D33+D34+D36+D37+D38+D39+D40+D41)))/Parametri!$C$77,Parametri!$C$78),Parametri!$C$80)+Parametri!$C$81)*(1-IF(Parametri!$C$64=1,Parametri!$C$82,0))) -> 0 | E35: =IF(Parametri!$C$77=0,0,Parametri!$C$77*(Parametri!$C$79*MIN(MAX(IF(Parametri!$C$64=1,E17*Parametri!$C$65,MAX(0,E28-(E31+E32+E33+E34+E36+E37+E38+E39+E40+E41)))/Parametri!$C$77,Parametri!$C$78),Parametri!$C$80)+Parametri!$C$81)*(1-IF(Parametri!$C$64=1,Parametri!$C$82,0))) -> 0 | F35: =IF(Parametri!$C$77=0,0,Parametri!$C$77*(Parametri!$C$79*MIN(MAX(IF(Parametri!$C$64=1,F17*Parametri!$C$65,MAX(0,F28-(F31+F32+F33+F34+F36+F37+F38+F39+F40+F41)))/Parametri!$C$77,Parametri!$C$78),Parametri!$C$80)+Parametri!$C$81)*(1-IF(Parametri!$C$64=1,Parametri!$C$82,0))) -> 0 | G35: =IF(Parametri!$C$77=0,0,Parametri!$C$77*(Parametri!$C$79*MIN(MAX(IF(Parametri!$C$64=1,G17*Parametri!$C$65,MAX(0,G28-(G31+G32+G33+G34+G36+G37+G38+G39+G40+G41)))/Parametri!$C$77,Parametri!$C$78),Parametri!$C$80)+Parametri!$C$81)*(1-IF(Parametri!$C$64=1,Parametri!$C$82,0))) -> 0 | H35: =IF(Parametri!$C$77=0,0,Parametri!$C$77*(Parametri!$C$79*MIN(MAX(IF(Parametri!$C$64=1,H17*Parametri!$C$65,MAX(0,H28-(H31+H32+H33+H34+H36+H37+H38+H39+H40+H41)))/Parametri!$C$77,Parametri!$C$78),Parametri!$C$80)+Parametri!$C$81)*(1-IF(Parametri!$C$64=1,Parametri!$C$82,0))) -> 0 | I35: =IF(Parametri!$C$77=0,0,Parametri!$C$77*(Parametri!$C$79*MIN(MAX(IF(Parametri!$C$64=1,I17*Parametri!$C$65,MAX(0,I28-(I31+I32+I33+I34+I36+I37+I38+I39+I40+I41)))/Parametri!$C$77,Parametri!$C$78),Parametri!$C$80)+Parametri!$C$81)*(1-IF(Parametri!$C$64=1,Parametri!$C$82,0))) -> 0 | J35: =IF(Parametri!$C$77=0,0,Parametri!$C$77*(Parametri!$C$79*MIN(MAX(IF(Parametri!$C$64=1,J17*Parametri!$C$65,MAX(0,J28-(J31+J32+J33+J34+J36+J37+J38+J39+J40+J41)))/Parametri!$C$77,Parametri!$C$78),Parametri!$C$80)+Parametri!$C$81)*(1-IF(Parametri!$C$64=1,Parametri!$C$82,0))) -> 0 | ... Q35: =IF(Parametri!$C$77=0,0,Parametri!$C$77*(Parametri!$C$79*MIN(MAX(IF(Parametri!$C$64=1,Q17*Parametri!$C$65,MAX(0,Q28-(Q31+Q32+Q33+Q34+Q36+Q37+Q38+Q39+Q40+Q41)))/Parametri!$C$77,Parametri!$C$78),Parametri!$C$80)+Parametri!$C$81)*(1-IF(Parametri!$C$64=1,Parametri!$C$82,0))) -> 0
A36: Fideiussione ADM | C36: =Parametri!$C$83 -> 500 | D36: =Parametri!$C$83 -> 500 | E36: =Parametri!$C$83 -> 500 | F36: =Parametri!$C$83 -> 500 | G36: =Parametri!$C$83 -> 500 | H36: =Parametri!$C$83 -> 500 | I36: =Parametri!$C$83 -> 500 | J36: =Parametri!$C$83 -> 500 | ... Q36: =Parametri!$C$83 -> 500
A37: Marketing e commerciale | C37: =Parametri!$C$84 -> 0 | D37: =Parametri!$C$84 -> 0 | E37: =Parametri!$C$84 -> 0 | F37: =Parametri!$C$84 -> 0 | G37: =Parametri!$C$84 -> 0 | H37: =Parametri!$C$84 -> 0 | I37: =Parametri!$C$84 -> 0 | J37: =Parametri!$C$84 -> 0 | ... Q37: =Parametri!$C$84 -> 0
A38: Manutenzione e ricambi | C38: =Parametri!$C$85*'Impianto e costi'!$G$70 -> 535.354 | D38: =Parametri!$C$85*'Impianto e costi'!$G$70 -> 535.354 | E38: =Parametri!$C$85*'Impianto e costi'!$G$70 -> 535.354 | F38: =Parametri!$C$85*'Impianto e costi'!$G$70 -> 535.354 | G38: =Parametri!$C$85*'Impianto e costi'!$G$70 -> 535.354 | H38: =Parametri!$C$85*'Impianto e costi'!$G$70 -> 535.354 | I38: =Parametri!$C$85*'Impianto e costi'!$G$70 -> 535.354 | J38: =Parametri!$C$85*'Impianto e costi'!$G$70 -> 535.354 | ... Q38: =Parametri!$C$85*'Impianto e costi'!$G$70 -> 535.354
A39: Analisi di laboratorio | C39: =Parametri!$C$86 -> 250 | D39: =Parametri!$C$86 -> 250 | E39: =Parametri!$C$86 -> 250 | F39: =Parametri!$C$86 -> 250 | G39: =Parametri!$C$86 -> 250 | H39: =Parametri!$C$86 -> 250 | I39: =Parametri!$C$86 -> 250 | J39: =Parametri!$C$86 -> 250 | ... Q39: =Parametri!$C$86 -> 250
A40: Rifiuti, abbonamenti, varie | C40: =Parametri!$C$87 -> 1000 | D40: =Parametri!$C$87 -> 1000 | E40: =Parametri!$C$87 -> 1000 | F40: =Parametri!$C$87 -> 1000 | G40: =Parametri!$C$87 -> 1000 | H40: =Parametri!$C$87 -> 1000 | I40: =Parametri!$C$87 -> 1000 | J40: =Parametri!$C$87 -> 1000 | ... Q40: =Parametri!$C$87 -> 1000
A41: Personale dipendente | C41: =Parametri!$C$88 -> 0 | D41: =Parametri!$C$88 -> 0 | E41: =Parametri!$C$88 -> 0 | F41: =Parametri!$C$88 -> 0 | G41: =Parametri!$C$88 -> 0 | H41: =Parametri!$C$88 -> 0 | I41: =Parametri!$C$88 -> 0 | J41: =Parametri!$C$88 -> 0 | ... Q41: =Parametri!$C$88 -> 0
...

Sheet Break-even
A1: Punto di pareggio e volume necessario
A2: Quanti litri bisogna vendere per coprire i costi fissi e per recuperare l'investimento in 5 anni (senza rate né interessi del mutuo).
A4: Voce | B4: Unità | C4: K220 | D4: Come si calcola
A5: Ricavo medio per litro venduto | B5: €/L | C5: =Parametri!$C$26*Parametri!$C$36+Parametri!$C$27*Parametri!$C$37/Parametri!$C$38 -> 4.4148641 | D5: Quota fusti × prezzo/L + quota bottiglie × prezzo/bottiglia ÷ 0,33
A6: Costo produzione per litro venduto (materie prime, detergenti, energia, acqua) | B6: €/L | C6: =((Parametri!$C$45+Parametri!$C$46)/100+Parametri!$C$48*Parametri!$C$49/100+Parametri!$C$50*Parametri!$C$51/100)/(1-Parametri!$C$28) -> 0.715625 | D6: Si divide per (1 − perdite) perché si produce più di quanto si vende
A7: Imballaggi bottiglie e consumabili fusti per litro venduto | B7: €/L | C7: =Parametri!$C$27/Parametri!$C$38*(Parametri!$C$52+Parametri!$C$53+Parametri!$C$54+Parametri!$C$55+Parametri!$C$56)+Parametri!$C$26*Parametri!$C$57/100 -> 0.22834165
A8: Accisa per litro venduto | B8: €/L | C8: =Parametri!$C$47*Parametri!$C$62*(1-Parametri!$C$63)/100 -> 0.244956 | D8: °P × aliquota × (1 − riduzione) ÷ 100
A9: Logistica per litro venduto | B9: €/L | C9: =C5*Parametri!$C$58 -> 0.1103716
A10: Margine di contribuzione per litro venduto | B10: €/L | C10: =C5-C6-C7-C8-C9 -> 3.1155699 | D10: Ricavo − costi variabili per litro
A11: Costi fissi annui a regime | B11: €/anno | C11: ='Business plan'!G42 -> 5725.354 | D11: Dal business plan (anno 5). L'INPS cresce con il reddito, quindi è solo approssimata
A12: Litri da vendere per il pareggio operativo | B12: L/anno | C12: =IF(C10<=0,"mai",C11/C10) -> 1837.6587 | D12: Costi fissi ÷ margine per litro (ante imposte e ammortamenti)
A13: Litri vendibili al massimo (capacità dopo perdite) | B13: L/anno | C13: =Parametri!$C$16*(1-Parametri!$C$28) -> 7948.8 | D13: Capacità × (1 − perdite)
A14: Il pareggio richiede questa quota della capacità | B14: % | C14: =IF(ISNUMBER(C12),C12/C13,"n/d") -> 0.23118693 | D14: Oltre 100% = serve più capacità (più tank o cotte più grandi)
A15: Esito | C15: =IF(ISNUMBER(C14),IF(C14<=1,"Pareggio entro la capacità","Pareggio OLTRE la capacità"),"Non raggiungibile") -> Pareggio entro la capacità
A16: Litri da vendere per rientrare in 5 anni (fissi + investimento ÷ 5) | B16: L/anno | C16: =IF(C10<=0,"mai",(C11+'Impianto e costi'!$G$73/5)/C10) -> 5709.2901 | D16: Approssimazione ante imposte, senza mutuo
A17: …in percentuale della capacità vendibile | B17: % | C17: =IF(ISNUMBER(C16),C16/C13,"n/d") -> 0.71825812
